Workbook

Sheet README
A1: Cancer in India - combined dataset (state forecasts, national NCRP estimates, registry data, Maharashtra profile)
A2: This workbook merges the original state-wise forecasting file (Kumar et al. 2026) with data extracted from three NCRP/ICMR PDFs: IJMR 2022 national estimates (S1), the Maharashtra cancer fact sheet 2021 (S2) and the JCO 2020 NCRP report (S3). Every table in the PDFs has been transcribed; figure-only data were read from the page images. Header colours: blue = source data, green = formula-derived.
A4: Sheet | B4: Source | C4: Contents | D4: Rows (approx.) | E4: Group
A5: Source Documents | B5: All | C5: Bibliographic details of the four source documents and which sheets come from each | D5: 4 | E5: Guide
A6: Key Findings (3 PDFs) | B6: S1-S3 | C6: Headline statistics, methods, coverage and data-quality facts from the three new PDFs, with page numbers | D6: 46 | E6: Guide
A7: Cross-Validation | B7: S1-S4 | C7: Formula checks between the sources (e.g. existing state totals vs NCRP national estimates) | D7: 24 | E7: Guide
A8: Data Notes | B8: All | C8: Assumptions, inferred readings, discrepancies and conventions | D8: 15 | E8: Guide
A9: State-wise Incidence | B9: S4 + S1 | C9: Original 37-state table, extended with region, PBCR representation, growth rates, shares and an all-India total | D9: 37 | E9: India - state
A10: India Sites 2022 | B10: S1 | C10: IJMR Table I: 2022 cases, crude and age-adjusted rates and cumulative risk by site and sex, with 2020 comparison | D10: 55 | E10: India - national
A11: India Sites 2020 | B11: S3 | C11: JCO Table 2: projected 2020 cases, crude rate and cumulative risk by site and sex | D11: 55 | E11: India - national
A12: India Age-Sex Sites | B12: S1 | C12: IJMR Table II: top five sites by age group (0-14, 15-39, 40-64, 65+) and sex | D12: 56 | E12: India - national
A13: India Top10 Sites 2022 | B13: S1 | C13: IJMR Fig. 1: top ten sites by sex, validated against Table I | D13: 20 | E13: India - national
A14: India Trend 2015-2025 | B14: S1 | C14: IJMR Table III: leading-site cases 2015, 2020, 2025 with growth rates | D14: 17 | E14: India - national
A15: India Age Structure | B15: S1 | C15: Population pyramid shares (census 2011 vs 2022 estimate) | D15: 16 | E15: India - national
A16: PBCR Incidence Table | B16: S3 | C16: JCO Table 1: incidence, cumulative risk and mortality for 28 PBCRs (plus 4 district rows) | D16: 32 | E16: India - registries
... A33: Full PDF Text | B33: S1-S4 | C33: Raw extracted text of every page of all four PDFs (new column A identifies the document) | D33: 43 | E33: Reference

Sheet Source Documents
A1: Ref | B1: File | C1: Title | D1: Authors / publisher | E1: Journal / series | F1: Year | G1: Volume / pages | H1: DOI / link | I1: Data period | J1: Geography and scope | K1: Sheets built from it
A2: S1 | B2: 1792240250346_cancer_dataset.pdf | C2: Cancer incidence estimates for 2022 & projection for 2025: Result from National Cancer Registry Programme, India | D2: Krishnan Sathishkumar, Meesha Chaturvedi, Priyanka Das, S. Stephen, Prashant Mathur (ICMR-NCDIR, Bengaluru) | E2: Indian Journal of Medical Research | F2: 2022 | G2: 156 (Oct & Nov), pp 598-607 | H2: DOI 10.4103/ijmr.ijmr_1821_22 | I2: Rates 2012-2016; estimates 2022; projection 2025 | J2: India national, by sex, age group and anatomical site; state/region PBCR representation | K2: India Sites 2022; India Age-Sex Sites; India Top10 Sites 2022; India Trend 2015-2025; India Age Structure; Method Comparison; State-wise Incidence (cols I-J); Key Findings
A3: S2 | B3: 1792240259450_FS_Maharashtra.pdf | C3: Profile of Cancer and Related Factors - Maharashtra | D3: ICMR-National Centre for Disease Informatics and Research (NCDIR), Bengaluru | E3: Cancer fact sheet series (NCRP) | F3: 2021 | G3: 11 pages (9 content pages) | H3: https://www.ncdirindia.org/ | I3: Registry data 2012-2016; projections 2020 and 2025 | J3: Maharashtra state: 8 PBCRs, 5 HBCRs, socio-demographic, health indicators and infrastructure | K3: MH PBCR Profile; MH Childhood Cancer; MH Sites & Tobacco; MH Projections; MH Socio-Health Profile; MH Health Infrastructure; Clinical Stage
A4: S3 | B4: 1792240259452_cancer_dataset_2.pdf | C4: Cancer Statistics, 2020: Report From National Cancer Registry Programme, India | D4: Prashant Mathur, Krishnan Sathishkumar, Meesha Chaturvedi, Priyanka Das, Kondalli Lakshminarayana Sudarshan, Stephen Santhappan, Vinodh Nallasamy, Anish John, Sandeep Narasimhan, Francis Selvaraj Roselind; ICMR-NCDIR-NCRP Investigator Group | E4: JCO Global Oncology (ASCO) | F4: 2020 | G4: 6:1063-1075 | H4: DOI 10.1200/GO.20.00122 | I4: Registry data 2012-2016; trends from 1982; projection 2020 | J4: India: 28 PBCRs and 58 HBCRs; incidence, mortality, trends, stage, treatment | K4: PBCR Incidence Table; Tobacco-related Cancers; Cancer Trends (APC); Clinical Stage; India Sites 2020; Key Findings
A5: S4 | B5: 1792240265018_final_excel.xlsx (existing content) | C5: State-wise forecasting of cancer incidence in India using a moderated exponential regression model incorporating healthcare system determinants | D5: Dileep Kumar, Navin Upadhyay, Himanshu Pandey | E5: International Journal of Community Medicine and Public Health | F5: 2026 | G5: 13(4):1867-1873 | H5: https://dx.doi.org/10.18203/2394-6040.ijcmph20261025 | I5: Observed 2019-2022; predicted 2026, 2030, 2045 | J5: India, 37 states/UTs | K5: State-wise Incidence; Article Details; Summary & Findings; Healthcare Moderators; Model & Forecasts; References; Full PDF Text (pages 1-7)

Sheet Key Findings (3 PDFs)
A1: Source | B1: Topic | C1: Finding / metric | D1: Value | E1: Unit | F1: Context / detail | G1: Page
A2: IJMR 2022 (Sathishkumar) | B2: Burden | C2: Estimated new cancer cases in India, 2022 | D2: 1461427 | E2: cases | F2: Crude rate 100.4 per 100,000; age-adjusted rate 107.0 per 100,000 | G2: 598, 600
A3: IJMR 2022 (Sathishkumar) | B3: Burden | C3: Estimated cases among females, 2022 | D3: 749251 | E3: cases | F3: Crude rate 105.4 per 100,000 | G3: 600
A4: IJMR 2022 (Sathishkumar) | B4: Burden | C4: Estimated cases among males, 2022 | D4: 712176 | E4: cases | F4: Crude rate 95.6 per 100,000 | G4: 600
A5: IJMR 2022 (Sathishkumar) | B5: Risk | C5: Lifetime risk of cancer (0-74 years) | D5: 1 in 9 | F5: Both sexes; lung cancer in males 1 in 67; breast cancer in females 1 in 29 | G5: 598, 600
A6: IJMR 2022 (Sathishkumar) | B6: Burden | C6: Largest site groups, both sexes | D6: Digestive 288,054; breast 221,757; genital 218,319; oral cavity & pharynx 198,438; respiratory 143,062 | E6: cases | F6: Five highest-burden groups | G6: 600
A7: IJMR 2022 (Sathishkumar) | B7: Leading sites | C7: Top five male sites, 2022 | D7: Lung 10.6; mouth 8.4; prostate 6.1; tongue 5.9; stomach 4.8 | E7: % of male cancers | F7: Liver (3.9%) is in the male top ten but not the female | G7: 600
A8: IJMR 2022 (Sathishkumar) | B8: Leading sites | C8: Top five female sites, 2022 | D8: Breast 28.8; cervix 10.6; ovary 6.2; corpus uteri 3.7; lung 3.7 | E8: % of female cancers | F8: Thyroid (3.6%) and gallbladder (2.7%) are in the female top ten but not the male | G8: 600
A9: IJMR 2022 (Sathishkumar) | B9: Childhood | C9: Leading childhood (0-14 yr) cancer | D9: Lymphoid leukaemia: boys 29.3%, girls 24.3% | F9: Abstract prints 29.2% / 24.2%; Table II prints 29.3% / 24.3%. Next: brain/NS (boys 12.4%, girls 14.3%) | G9: 598, 600, 604
A10: IJMR 2022 (Sathishkumar) | B10: Childhood | C10: Childhood share of all cancers | D10: Boys 3.0%; girls 1.8% | E10: of cancers in age group 0-14 | F10: Rural childhood incidence is lower, attributed to under-reporting | G10: 606
A11: IJMR 2022 (Sathishkumar) | B11: Age | C11: Cancer cases in 40-64 year olds | D11: Males 341,230; females 425,918 | E11: cases | F11: Half of India's estimated burden is in this age group; globally half is aged 65+, in India one-third | G11: 600, 604, 606
A12: IJMR 2022 (Sathishkumar) | B12: Age | C12: Age-specific incidence rate pattern | D12: Rises from age 25; female > male at 25-59; male > female above 60 | F12: At 75+: males 710.6 vs females 451.7 per 100,000 | G12: 600
A13: IJMR 2022 (Sathishkumar) | B13: Age | C13: Peak number of cases by age group | D13: Age 60-64: males 106,296; females 105,139 | E13: cases | G13: 600
A14: IJMR 2022 (Sathishkumar) | B14: Projection | C14: Cases projected for 2025 | D14: 1.57 million (2025) vs 1.46 million (2022) | F14: Increase of 12.8% in 2025 vs 2020; +27.7% from 2015 to 2025 | G14: 598, 600
A15: IJMR 2022 (Sathishkumar) | B15: Projection | C15: 2025 leading-site projections | D15: Lung (males) 81,219; breast (females) 232,832 | E15: cases | F15: Table III | G15: 600, 605
A16: IJMR 2022 (Sathishkumar) | B16: Comparison | C16: 2022 estimate vs 2020 estimate (1,392,179) | D16: About +5% | F16: 13,92,179 in 2020 to 14,61,427 in 2022 | G16: 603
A17: IJMR 2022 (Sathishkumar) | B17: Comparison | C17: Lung cancer cases 2022 | D17: 103371 | E17: cases | F17: Top-five site for both sexes | G17: 603
A18: IJMR 2022 (Sathishkumar) | B18: Comparison | C18: GLOBOCAN context | D18: 19.3 million cases worldwide (2020); India third; India 2.08 million by 2040 (+57.5% vs 2020) | F18: NCRP 2020 estimate was 5.1% higher than GLOBOCAN | G18: 598, 604
A19: IJMR 2022 (Sathishkumar) | B19: Population | C19: Share of population aged 60+ | D19: 8.6% (2011) to 9.7% (2022) | F19: Ageing drives most of the projected rise because rates are held constant | G19: 605
A20: IJMR 2022 (Sathishkumar) | B20: Coverage | C20: PBCR coverage | D20: 28 PBCRs cover ~10% of population; NCRP coverage 16.4% (urban 31.6%, rural 9.5%) | F20: Of 28 PBCRs: 1 rural (3.5%), 12 urban (42.9%), 15 semi-urban (53.6%). Four NE states (Sikkim, Manipur, Mizoram, Tripura) have 100% PBCR coverage | G20: 599, 604, 605
A21: IJMR 2022 (Sathishkumar) | B21: Method | C21: Estimation approach | D21: 2012-16 age-specific rates by site applied to 2022 population estimates | F21: Constant incidence assumed; census 2021 delayed; fertility, mortality, migration and COVID-19 impact not modelled; only 6 PBCRs have >25 years of data | G21: 599-600, 604-605
A22: IJMR 2022 (Sathishkumar) | B22: Risk factors | C22: Attributable risk (DALYs) | D22: Alcohol 30.1% (pharyngeal); tobacco 43% and air pollution 43% (lung); diet 43.2% (colorectal) | F22: Rising incidence: tongue, mouth, colon, rectum, liver, lung, breast, corpus uteri, ovary, thyroid, prostate, gallbladder, pancreas, kidney, bladder, brain, NHL, lymphoid leukaemia. Falling: hypopharynx, oesophagus, stomach, cervix | G22: 605
A23: IJMR 2022 (Sathishkumar) | B23: Burden | C23: Projected DALYs from cancer by 2025 | D23: 29.8 million | E23: DALYs | F23: Separate NCRP publication cited in the paper | G23: 606
A24: JCO 2020 (Mathur) | B24: Projection | C24: Projected cases in India, 2020 | D24: 1392179 | E24: cases | F24: Males 679,421 (94.1 per 100,000); females 712,758 (103.6); crude rate both sexes 98.7 | G24: 1063, 1069
A25: JCO 2020 (Mathur) | B25: Risk | C25: Lifetime risk | D25: 1 in 68 males (lung); 1 in 29 females (breast); 1 in 9 Indians | F25: Cumulative risk age 0-74 | G25: 1069
A26: JCO 2020 (Mathur) | B26: Leading sites | C26: Five most common projected cancers 2020 | D26: Males: lung, mouth, prostate, tongue, stomach = 36% of male cancers; females: breast, cervix, ovary, corpus uteri, lung = 53% | G26: 1069
A27: JCO 2020 (Mathur) | B27: Geography | C27: Highest age-adjusted incidence | D27: Males: Aizawl district 269.4 (mortality 152.7); females: Papumpare district 219.8 | E27: per 100,000 | F27: Aizawl ~2x Delhi (147.0); East Khasi Hills 227.9, Kamrup urban 213.0, Mizoram state 207.0 follow | G27: 1066
A28: JCO 2020 (Mathur) | B28: Geography | C28: Highest outside the North-East | D28: Males: Delhi 147.0, Thiruvananthapuram 137.8; females: Bangalore 146.8, Delhi 141.0 | E28: per 100,000 | G28: 1066
A29: JCO 2020 (Mathur) | B29: Geography | C29: Lowest age-adjusted incidence | D29: Osmanabad and Beed: males 39.5, females 49.4 | E29: per 100,000 | F29: Aizawl male rate ~7x and Papumpare female rate ~4x that of Osmanabad & Beed; Barshi rural is ~1/3 of urban PBCRs | G29: 1068-1070
A30: JCO 2020 (Mathur) | B30: Geography | C30: One in four lifetime risk | D30: Males in Aizawl, Papumpare, East Khasi Hills, Kamrup urban; females in Papumpare (1 in 4) and Mizoram (1 in 5) | F30: Cumulative risk 0-74 | G30: 1066
A31: JCO 2020 (Mathur) | B31: Tobacco | C31: Tobacco-associated share of cancers | D31: East Khasi Hills: 70.4% males, 46.5% females | E31: % | F31: About one-third of cancers in India are tobacco-associated; NE highest, then West and Central registries | G31: 1066-1067, 1071
A32: JCO 2020 (Mathur) | B32: Patterns | C32: Most common sites in registries | D32: Men: lung (9 PBCRs), mouth (9), oesophagus (5), stomach (4), nasopharynx (1); women: breast (19 PBCRs), cervix (7) | F32: Thyroid second in Thiruvananthapuram and Kollam; lung in Manipur and Mizoram (women) | G32: 1067, 1069
A33: JCO 2020 (Mathur) | B33: Stage | C33: Loco-regional at diagnosis | D33: Breast 57.0%; cervix 60.0%; head & neck 66.6%; stomach 50.8% | E33: % | F33: Lung: distant metastasis 44.0% (males), 47.6% (females). See sheet Clinical Stage | G33: 1063, 1068
A34: JCO 2020 (Mathur) | B34: Treatment | C34: Multimodality treatment share | D34: Loco-regional 79.5%; localised 74.4%; distant metastasis 47.6% | E34: % | F34: Systemic therapy most common for lung and stomach; chemoradiation for cervix | G34: 1068, 1071
A35: JCO 2020 (Mathur) | B35: Trends | C35: Annual percentage change | D35: All sites increasing in 12 PBCRs (males) and 13 (females); highest Kamrup urban 3.8% | E35: % per year | F35: Breast: significant increase everywhere except Nagpur; cervix: significant decrease in 10 PBCRs; lung (females): significant increase in 11. See sheet Cancer Trends (APC) | G35: 1063, 1068
A36: JCO 2020 (Mathur) | B36: Data quality | C36: Quality indices across 28 PBCRs | D36: MV% 77 (Patiala) to 96.7 (Hyderabad); DCO% <0.05 (Osmanabad & Beed) to 19.4 (Patiala); O&U% 1.8 (Hyderabad) to 13.0 (Patiala) | F36: Highest mortality-to-incidence ratio: Barshi rural 67.2%, Wardha 59.2%, Mumbai 56.0% | G36: 1068
A37: JCO 2020 (Mathur) | B37: Coverage | C37: Registry network analysed | D37: 28 PBCRs and 58 HBCRs (667,666 patients) of 36 PBCRs and 236 HBCRs registered | F37: PBCRs cover ~100 million person-years (~10% of India); trend analysis uses 16 PBCRs with 11-35 years of data | G37: 1064-1065, 1071
A38: JCO 2020 (Mathur) | B38: Comparison | C38: NCRP vs IARC/GLOBOCAN 2018 national estimate | D38: 1,392,179 (NCRP, 2020) vs 1,157,294 (2018) | E38: cases | F38: Difference attributed to methodology and use of recent data | G38: 1072
A39: JCO 2020 (Mathur) | B39: Prevention | C39: Preventable share of cancers | D39: Approximately 70% | F39: Tobacco and air pollution main lung-cancer risk factors; breast and cervix need screening/awareness | G39: 1071
A40: JCO 2020 (Mathur) | B40: Context | C40: NCD burden | D40: NCDs: 71% of deaths globally, 63% in India; cancer 9% of deaths in India | G40: 1063
...

Sheet Cross-Validation
A1: # | B1: Check | C1: Value A - description | D1: Value A | E1: Value B - description | F1: Value B | G1: Difference (A - B) | H1: Tolerance | I1: Status | J1: Comment
A2: 1 | B2: India 2020 cases | C2: Sum of 37 states, "2020 Observed" (existing sheet) | D2: ='State-wise Incidence'!C39 -> 1392179 | E2: JCO 2020 projected national cases | F2: ='India Sites 2020'!J2 -> 1392179 | G2: =D2-F2 -> 0 | H2: 0 | I2: =IF(ABS(G2)<=H2,"Match","Check") -> Match | J2: Identical: the existing "observed" 2020 column is the NCRP national projection, not raw registry counts.
A3: 2 | B3: India 2022 cases | C3: Sum of 37 states, "2022 Observed" (existing sheet) | D3: ='State-wise Incidence'!E39 -> 1461427 | E3: IJMR 2022 estimated national cases (Table I) | F3: ='India Sites 2022'!L2 -> 1461427 | G3: =D3-F3 -> 0 | H3: 0 | I3: =IF(ABS(G3)<=H3,"Match","Check") -> Match | J3: Identical: the existing "2022 Observed" column equals the IJMR NCRP estimate.
A4: 3 | B4: Maharashtra 2020 cases | C4: Maharashtra "2020 Observed" (existing sheet) | D4: =INDEX('State-wise Incidence'!$C$2:$C$38,MATCH("Maharashtra",'State-wise Incidence'!$A$2:$A$38,0)) -> 116121 | E4: Fact sheet projection 2020 (M + F) | F4: ='MH Projections'!D2 -> 116121 | G4: =D4-F4 -> 0 | H4: 0 | I4: =IF(ABS(G4)<=H4,"Match","Check") -> Match | J4: Identical: state data trace back to NCRP projections.
A5: 4 | B5: Maharashtra share of India, 2020 | C5: Existing-sheet Maharashtra / India 2020 | D5: =INDEX('State-wise Incidence'!$C$2:$C$38,MATCH("Maharashtra",'State-wise Incidence'!$A$2:$A$38,0))/'State-wise Incidence'!C39 -> 0.083409533 | E5: Fact-sheet Maharashtra / JCO India 2020 | F5: ='MH Projections'!G2 -> 0.083409533 | G5: =D5-F5 -> 0 | H5: 1e-05 | I5: =IF(ABS(G5)<=H5,"Match","Check") -> Match
A6: 5 | B6: India 2020 cases across papers | C6: IJMR Table III both sexes 2020 | D6: ='India Trend 2015-2025'!D18 -> 1392179 | E6: JCO Table 2 all sites 2020 | F6: ='India Sites 2020'!J2 -> 1392179 | G6: =D6-F6 -> 0 | H6: 0 | I6: =IF(ABS(G6)<=H6,"Match","Check") -> Match | J6: Two NCRP papers agree on the 2020 projection.
A7: 6 | B7: IJMR 2022 male + female = both sexes | C7: Male + female cases (Table I) | D7: ='India Sites 2022'!D2+'India Sites 2022'!H2 -> 1461427 | E7: Both sexes cases (Table I) | F7: ='India Sites 2022'!L2 -> 1461427 | G7: =D7-F7 -> 0 | H7: 0 | I7: =IF(ABS(G7)<=H7,"Match","Check") -> Match | J7: Internal consistency of Table I.
A8: 7 | B8: 2025 vs 2020 growth (%) | C8: Computed from Table III (rounded to 0.1) | D8: =ROUND('India Trend 2015-2025'!G18*100,1) -> 12.8 | E8: Paper text | F8: 12.8 | G8: =D8-F8 -> 0 | H8: 0.05 | I8: =IF(ABS(G8)<=H8,"Match","Check") -> Match
A9: 8 | B9: 2025 vs 2015 growth (%) | C9: Computed from Table III (rounded to 0.1) | D9: =ROUND('India Trend 2015-2025'!H18*100,1) -> 27.7 | E9: Paper text | F9: 27.7 | G9: =D9-F9 -> 0 | H9: 0.05 | I9: =IF(ABS(G9)<=H9,"Match","Check") -> Match
A10: 9 | B10: 2022 vs 2020 growth (%) | C10: Computed from Table I and JCO Table 2 | D10: =ROUND(('India Sites 2022'!L2/'India Sites 2020'!J2-1)*100,1) -> 5 | E10: Paper text ("five per cent") | F10: 5 | G10: =D10-F10 -> 0 | H10: 0.1 | I10: =IF(ABS(G10)<=H10,"Match","Check") -> Match | J10: Text rounds 4.98% to 5%.
A11: 10 | B11: Lung cancer cases 2022 | C11: Table I, lung and bronchus, both sexes | D11: =INDEX('India Sites 2022'!$L$2:$L$58,MATCH("Lung and bronchus",'India Sites 2022'!$A$2:$A$58,0)) -> 103371 | E11: Paper discussion text (1,03,371) | F11: 103371 | G11: =D11-F11 -> 0 | H11: 0 | I11: =IF(ABS(G11)<=H11,"Match","Check") -> Match
A12: 11 | B12: Population aged 60+, 2022 (%) | C12: Pyramid data, male/female average | D12: =ROUND('India Age Structure'!D21,1) -> 9.7 | E12: Paper text | F12: 9.7 | G12: =D12-F12 -> 0 | H12: 0.05 | I12: =IF(ABS(G12)<=H12,"Match","Check") -> Match | J12: Confirms which pyramid is 2022.
A13: 12 | B13: Population aged 60+, 2011 (%) | C13: Pyramid data, male/female average | D13: =ROUND('India Age Structure'!B21,1) -> 8.6 | E13: Paper text | F13: 8.6 | G13: =D13-F13 -> 0 | H13: 0.05 | I13: =IF(ABS(G13)<=H13,"Match","Check") -> Match | J13: Confirms which pyramid is 2011.
A14: 13 | B14: Lymphoid leukaemia share, boys 0-14 (%) | C14: Table II (printed) | D14: ='India Age-Sex Sites'!G2 -> 29.3 | E14: Abstract (printed) | F14: 29.2 | G14: =D14-F14 -> 0.1 | H14: 0.05 | I14: =IF(ABS(G14)<=H14,"Match","Check") -> Check | J14: Source discrepancy: abstract 29.2% vs table 29.3% (table used in workbook).
A15: 14 | B15: Lymphoid leukaemia share, girls 0-14 (%) | C15: Table II (printed) | D15: ='India Age-Sex Sites'!G9 -> 24.3 | E15: Abstract (printed) | F15: 24.2 | G15: =D15-F15 -> 0.1 | H15: 0.05 | I15: =IF(ABS(G15)<=H15,"Match","Check") -> Check | J15: Source discrepancy: abstract 24.2% vs table 24.3% (table used in workbook).
A16: 15 | B16: Tobacco shares: printed vs recomputed | C16: Mean absolute difference, 32 registries x 2 sexes (pct-pts) | D16: =(SUMPRODUCT(ABS('Tobacco-related Cancers'!I2:I33-'Tobacco-related Cancers'!C2:C33))+SUMPRODUCT(ABS('Tobacco-related Cancers'!J2:J33-'Tobacco-related Cancers'!F2:F33)))/64 -> 0.098638006 | E16: Expected | F16: 0 | G16: =D16-F16 -> 0.098638006 | H16: 0.5 | I16: =IF(ABS(G16)<=H16,"Match","Check") -> Match | J16: Small differences are rounding in the printed rates.
A17: 16 | B17: Stage rows not summing to ~100% | C17: Rows with |total - 100| > 0.15 | D17: =SUMPRODUCT(--(ABS('Clinical Stage'!I2:I15-100)>0.15)) -> 0 | E17: Expected | F17: 0 | G17: =D17-F17 -> 0 | H17: 0 | I17: =IF(ABS(G17)<=H17,"Match","Check") -> Match
A18: 17 | B18: Breast: significant APC increases | C18: Count in Cancer Trends (APC) | D18: =COUNTIFS('Cancer Trends (APC)'!A2:A153,"Breast",'Cancer Trends (APC)'!F2:F153,"Yes") -> 15 | E18: Paper: all registries except Nagpur (16 analysed) | F18: 15 | G18: =D18-F18 -> 0 | H18: 0 | I18: =IF(ABS(G18)<=H18,"Match","Check") -> Match
A19: 18 | B19: Cervix: significant APC decreases | C19: Count in Cancer Trends (APC) | D19: =COUNTIFS('Cancer Trends (APC)'!A2:A153,"Cervix uteri",'Cancer Trends (APC)'!F2:F153,"Yes") -> 10 | E19: Paper text | F19: 10 | G19: =D19-F19 -> 0 | H19: 0 | I19: =IF(ABS(G19)<=H19,"Match","Check") -> Match
A20: 19 | B20: Lung (female): significant APC increases | C20: Count in Cancer Trends (APC) | D20: =COUNTIFS('Cancer Trends (APC)'!A2:A153,"Lung",'Cancer Trends (APC)'!B2:B153,"Female",'Cancer Trends (APC)'!F2:F153,"Yes") -> 11 | E20: Paper text | F20: 11 | G20: =D20-F20 -> 0 | H20: 0 | I20: =IF(ABS(G20)<=H20,"Match","Check") -> Match
A21: 20 | B21: All sites (male): registries with rising trend | C21: Count APC > 0 | D21: =COUNTIFS('Cancer Trends (APC)'!A2:A153,"All sites",'Cancer Trends (APC)'!B2:B153,"Male",'Cancer Trends (APC)'!E2:E153,">0") -> 12 | E21: Paper text | F21: 12 | G21: =D21-F21 -> 0 | H21: 0 | I21: =IF(ABS(G21)<=H21,"Match","Check") -> Match
A22: 21 | B22: All sites (female): registries with rising trend | C22: Count APC > 0 | D22: =COUNTIFS('Cancer Trends (APC)'!A2:A153,"All sites",'Cancer Trends (APC)'!B2:B153,"Female",'Cancer Trends (APC)'!E2:E153,">0") -> 13 | E22: Paper text | F22: 13 | G22: =D22-F22 -> 0 | H22: 0 | I22: =IF(ABS(G22)<=H22,"Match","Check") -> Match
A23: 22 | B23: Gender ratio, Maharashtra | C23: Recomputed from population | D23: ='MH Socio-Health Profile'!E17 -> 929.4031 | E23: Fact sheet (printed) | F23: 929 | G23: =D23-F23 -> 0.40310344 | H23: 0.5 | I23: =IF(ABS(G23)<=H23,"Match","Check") -> Match | J23: Printed value is rounded.
A24: 23 | B24: Existing 2026 projection vs IJMR 2025 projection | C24: Sum of states, Predicted 2026 (Kumar 2026) | D24: ='State-wise Incidence'!F39 -> 1604194 | E24: IJMR 2022 projected 2025 (both sexes) | F24: ='India Trend 2015-2025'!E18 -> 1569793 | G24: =D24-F24 -> 34401 | I24: Info only | J24: Different target years (2026 vs 2025) and different models; shown for context only.
A25: 24 | B25: Fact-sheet map values vs JCO Table 1 | C25: Annual cases, crude rates and age-adjusted rates for the 7 Maharashtra PBCRs (fact sheet p3) | E25: JCO 2020 Table 1 | I25: Match (manual) | J25: All 7 registries x 2 sexes x 3 measures were compared by eye; no differences. The childhood-cancer map has no counterpart in JCO.
B27: Summary: checks passing | I27: =COUNTIF(I2:I25,"Match*")&" of "&COUNTA(I2:I25) -> 21 of 24

Sheet State-wise Incidence
A1: State/UT | B1: 2019 Observed | C1: 2020 Observed | D1: 2021 Observed | E1: 2022 Observed | F1: Predicted 2026 | G1: Predicted 2030 | H1: Predicted 2045 | I1: Region (NCRP zone) | J1: NCRP PBCR representation used for state estimates | K1: CAGR 2019-22 (observed) | L1: CAGR 2022-26 (projected) | M1: CAGR 2022-45 (projected) | N1: Share of all-India 2022 cases | O1: Projected 2045 / 2022 (x)
A2: Jammu and Kashmir | B2: 12396 | C2: 12726 | D2: 13060 | E2: 13395 | F2: 14857 | G2: 16475 | H2: 24277 | I2: North | J2: Pooled Rest of India | K2: =(E2/B2)^(1/3)-1 -> 0.026172527 | L2: =(F2/E2)^(1/4)-1 -> 0.026235659 | M2: =(H2/E2)^(1/23)-1 -> 0.026191377 | N2: =E2/E$39 -> 0.009165699 | O2: =H2/E2 -> 1.8123927
A3: Ladakh | B3: 279 | C3: 286 | D3: 294 | E3: 302 | F3: 336 | G3: 373 | H3: 556 | I3: North | J3: Pooled Rest of India | K3: =(E3/B3)^(1/3)-1 -> 0.026756781 | L3: =(F3/E3)^(1/4)-1 -> 0.027029891 | M3: =(H3/E3)^(1/23)-1 -> 0.026891807 | N3: =E3/E$39 -> 0.00020664734 | O3: =H3/E3 -> 1.8410596
A4: Himachal Pradesh | B4: 8589 | C4: 8799 | D4: 8978 | E4: 9164 | F4: 9992 | G4: 10887 | H4: 15021 | I4: North | J4: Pooled Rest of India | K4: =(E4/B4)^(1/3)-1 -> 0.021835122 | L4: =(F4/E4)^(1/4)-1 -> 0.021861028 | M4: =(H4/E4)^(1/23)-1 -> 0.021717973 | N4: =E4/E$39 -> 0.0062705835 | O4: =H4/E4 -> 1.6391314
A5: Punjab | B5: 37744 | C5: 38636 | D5: 39521 | E5: 40435 | F5: 44322 | G5: 48578 | H5: 68516 | I5: North | J5: Patiala | K5: =(E5/B5)^(1/3)-1 -> 0.023221934 | L5: =(F5/E5)^(1/4)-1 -> 0.023211648 | M5: =(H5/E5)^(1/23)-1 -> 0.023194093 | N5: =E5/E$39 -> 0.027668163 | O5: =H5/E5 -> 1.6944726
A6: Chandigarh | B6: 994 | C6: 1024 | D6: 1053 | E6: 1088 | F6: 1225 | G6: 1381 | H6: 2162 | I6: North | J6: Pooled Rest of India | K6: =(E6/B6)^(1/3)-1 -> 0.030577928 | L6: =(F6/E6)^(1/4)-1 -> 0.03009386 | M6: =(H6/E6)^(1/23)-1 -> 0.030306364 | N6: =E6/E$39 -> 0.00074447783 | O6: =H6/E6 -> 1.9871324
A7: Uttaranchal | B7: 11216 | C7: 11482 | D7: 11779 | E7: 12065 | F7: 13305 | G7: 14671 | H7: 21170 | I7: North | J7: Pooled Rest of India | K7: =(E7/B7)^(1/3)-1 -> 0.02462066 | L7: =(F7/E7)^(1/4)-1 -> 0.024759347 | M7: =(H7/E7)^(1/23)-1 -> 0.024748072 | N7: =E7/E$39 -> 0.0082556296 | O7: =H7/E7 -> 1.7546622
A8: Haryana | B8: 28453 | C8: 29219 | D8: 30015 | E8: 30851 | F8: 34356 | G8: 38269 | H8: 57344 | I8: North | J8: Pooled Rest of India | K8: =(E8/B8)^(1/3)-1 -> 0.027338887 | L8: =(F8/E8)^(1/4)-1 -> 0.027267 | M8: =(H8/E8)^(1/23)-1 -> 0.027318627 | N8: =E8/E$39 -> 0.021110189 | O8: =H8/E8 -> 1.8587404
A9: Delhi | B9: 24436 | C9: 25178 | D9: 25969 | E9: 26735 | F9: 30163 | G9: 34017 | H9: 53405 | I9: North | J9: Delhi | K9: =(E9/B9)^(1/3)-1 -> 0.030425721 | L9: =(F9/E9)^(1/4)-1 -> 0.030620048 | M9: =(H9/E9)^(1/23)-1 -> 0.030541042 | N9: =E9/E$39 -> 0.018293764 | O9: =H9/E9 -> 1.9975687
A10: Rajasthan | B10: 69156 | C10: 70987 | D10: 72825 | E10: 74725 | F10: 82850 | G10: 91854 | H10: 135242 | I10: Central | J10: Pooled Rest of India | K10: =(E10/B10)^(1/3)-1 -> 0.026152764 | L10: =(F10/E10)^(1/4)-1 -> 0.026140071 | M10: =(H10/E10)^(1/23)-1 -> 0.026129056 | N10: =E10/E$39 -> 0.051131531 | O10: =H10/E10 -> 1.8098628
A11: Uttar Pradesh | B11: 196652 | C11: 201319 | D11: 206088 | E11: 210958 | F11: 231671 | G11: 254411 | H11: 361432 | I11: Central | J11: Pooled Rest of India | K11: =(E11/B11)^(1/3)-1 -> 0.02368391 | L11: =(F11/E11)^(1/4)-1 -> 0.023691079 | M11: =(H11/E11)^(1/23)-1 -> 0.023685491 | N11: =E11/E$39 -> 0.14435069 | O11: =H11/E11 -> 1.7132889
A12: Bihar | B12: 101014 | C12: 103711 | D12: 106435 | E12: 109274 | F12: 121330 | G12: 134721 | H12: 199495 | I12: East | J12: Pooled Rest of India | K12: =(E12/B12)^(1/3)-1 -> 0.026546021 | L12: =(F12/E12)^(1/4)-1 -> 0.026509184 | M12: =(H12/E12)^(1/23)-1 -> 0.026516364 | N12: =E12/E$39 -> 0.074772123 | O12: =H12/E12 -> 1.8256401
A13: Sikkim | B13: 443 | C13: 445 | D13: 465 | E13: 496 | F13: 570 | G13: 664 | H13: 1180 | I13: North East | J13: Sikkim state | K13: =(E13/B13)^(1/3)-1 -> 0.038387178 | L13: =(F13/E13)^(1/4)-1 -> 0.035376479 | M13: =(H13/E13)^(1/23)-1 -> 0.038401321 | N13: =E13/E$39 -> 0.0003393943 | O13: =H13/E13 -> 2.3790323
... A38: Andaman and Nicobar Islands | B38: 357 | C38: 366 | D38: 380 | E38: 393 | F38: 447 | G38: 509 | H38: 830 | I38: South | J38: Pooled South | K38: =(E38/B38)^(1/3)-1 -> 0.032542916 | L38: =(F38/E38)^(1/4)-1 -> 0.032710858 | M38: =(H38/E38)^(1/23)-1 -> 0.033039107 | N38: =E38/E$39 -> 0.00026891525 | O38: =H38/E38 -> 2.1119593
A39: All India (sum of 37 states/UTs) | B39: =SUM(B2:B38) -> 1358415 | C39: =SUM(C2:C38) -> 1392179 | D39: =SUM(D2:D38) -> 1426447 | E39: =SUM(E2:E38) -> 1461427 | F39: =SUM(F2:F38) -> 1604194 | G39: =SUM(G2:G38) -> 1766486 | H39: =SUM(H2:H38) -> 2547851 | K39: =(E39/B39)^(1/3)-1 -> 0.024664176 | L39: =(F39/E39)^(1/4)-1 -> 0.023575637 | M39: =(H39/E39)^(1/23)-1 -> 0.024461206 | N39: =E39/E$39 -> 1 | O39: =H39/E39 -> 1.7433994
A40: Source note | B40: Values transcribed from Table 1 in the uploaded PDF. State/UT labels are retained as printed in the source (e.g., Uttaranchal, Orissa, Pondicherry, Daman).
A41: Added columns | B41: Columns I-J: region and PBCR representation from Supplementary Table I of the IJMR 2022 paper (Sathishkumar et al.). Columns K-O (green headers) are formulas derived from columns B-H; row 39 sums the 37 states/UTs.
A42: Important caveat | B42: The all-India sums for "2020 Observed" (1,392,179) and "2022 Observed" (1,461,427) equal the NCRP national ESTIMATES published in the JCO 2020 and IJMR 2022 papers; Maharashtra 2020 (116,121) equals the NCRP Maharashtra projection (54,961 + 61,160). These columns are therefore model-based NCRP estimates, not raw registry counts. See sheet Cross-Validation.

Sheet India Sites 2022
A1: Site (ICD-10 group) | B1: Level | C1: Parent group | D1: Male - estimated cases 2022 | E1: Male - crude rate /100,000 | F1: Male - age-adjusted rate /100,000 | G1: Male - cum. risk 0-74 (1 in N) | H1: Female - estimated cases 2022 | I1: Female - crude rate /100,000 | J1: Female - age-adjusted rate /100,000 | K1: Female - cum. risk 0-74 (1 in N) | L1: Both sexes - estimated cases 2022 | M1: Both sexes - crude rate /100,000 | N1: Both sexes - age-adjusted rate /100,000 | O1: Both sexes - cum. risk 0-74 (1 in N) | P1: Share of all-site cases (both sexes) | Q1: Female : male case ratio | R1: Both sexes - 2020 projected cases (JCO) | S1: Change in cases 2020 to 2022
A2: All sites | B2: Total | D2: 712176 | E2: 95.6 | F2: 105.7 | G2: 9 | H2: 749251 | I2: 105.4 | J2: 109 | K2: 9 | L2: 1461427 | M2: 100.4 | N2: 107 | O2: 9 | P2: =L2/L$2 -> 1 | Q2: =IF(AND(ISNUMBER(D2),ISNUMBER(H2)),H2/D2,"") -> 1.0520588 | R2: ='India Sites 2020'!J2 -> 1392179 | S2: =L2/R2-1 -> 0.04974073
A3: Oral cavity and pharynx | B3: Group | D3: 145844 | E3: 19.6 | F3: 21.2 | G3: 42 | H3: 52594 | I3: 7.4 | J3: 7.7 | K3: 115 | L3: 198438 | M3: 13.6 | N3: 14.4 | O3: 62 | P3: =L3/L$2 -> 0.13578372 | Q3: =IF(AND(ISNUMBER(D3),ISNUMBER(H3)),H3/D3,"") -> 0.36061819 | R3: ='India Sites 2020'!J3 -> 188969 | S3: =L3/R3-1 -> 0.050108748
A4: Tongue | B4: Site | C4: Oral cavity and pharynx | D4: 41845 | E4: 5.6 | F4: 6 | G4: 147 | H4: 14611 | I4: 2.1 | J4: 2.1 | K4: 400 | L4: 56456 | M4: 3.9 | N4: 4.1 | O4: 215 | P4: =L4/L$2 -> 0.038630736 | Q4: =IF(AND(ISNUMBER(D4),ISNUMBER(H4)),H4/D4,"") -> 0.34916955 | R4: ='India Sites 2020'!J4 -> 53772 | S4: =L4/R4-1 -> 0.049914454
A5: Mouth | B5: Site | C5: Oral cavity and pharynx | D5: 60164 | E5: 8.1 | F5: 8.6 | G5: 103 | H5: 23675 | I5: 3.3 | J5: 3.5 | K5: 241 | L5: 83839 | M5: 5.8 | N5: 6.1 | O5: 144 | P5: =L5/L$2 -> 0.057367901 | Q5: =IF(AND(ISNUMBER(D5),ISNUMBER(H5)),H5/D5,"") -> 0.39350775 | R5: ='India Sites 2020'!J5 -> 79863 | S5: =L5/R5-1 -> 0.049785257
A6: Pharynx | B6: Site | C6: Oral cavity and pharynx | D6: 3177 | E6: 0.4 | F6: 0.5 | G6: 1793 | H6: 1168 | I6: 0.2 | J6: 0.2 | K6: 5482 | L6: 4345 | M6: 0.3 | N6: 0.3 | O6: 2704 | P6: =L6/L$2 -> 0.0029731215 | Q6: =IF(AND(ISNUMBER(D6),ISNUMBER(H6)),H6/D6,"") -> 0.36764243 | R6: ='India Sites 2020'!J6 -> 4131 | S6: =L6/R6-1 -> 0.051803437
A7: Other oral cavity | B7: Site | C7: Oral cavity and pharynx | D7: 40658 | E7: 5.5 | F7: 6.1 | G7: 137 | H7: 13140 | I7: 1.8 | J7: 1.9 | K7: 475 | L7: 53798 | M7: 3.7 | N7: 4 | O7: 213 | P7: =L7/L$2 -> 0.036811965 | Q7: =IF(AND(ISNUMBER(D7),ISNUMBER(H7)),H7/D7,"") -> 0.32318363 | R7: ='India Sites 2020'!J7 -> 51203 | S7: =L7/R7-1 -> 0.050680624
A8: Digestive system | B8: Group | D8: 172025 | E8: 23.1 | F8: 25.9 | G8: 32 | H8: 116029 | I8: 16.3 | J8: 17 | K8: 50 | L8: 288054 | M8: 19.8 | N8: 21.4 | O8: 39 | P8: =L8/L$2 -> 0.19710461 | Q8: =IF(AND(ISNUMBER(D8),ISNUMBER(H8)),H8/D8,"") -> 0.67448917 | R8: ='India Sites 2020'!J8 -> 273982 | S8: =L8/R8-1 -> 0.051361038
A9: Oesophagus | B9: Site | C9: Digestive system | D9: 34272 | E9: 4.6 | F9: 5.2 | G9: 159 | H9: 21300 | I9: 3 | J9: 3.1 | K9: 263 | L9: 55572 | M9: 3.8 | N9: 4.2 | O9: 198 | P9: =L9/L$2 -> 0.038025847 | Q9: =IF(AND(ISNUMBER(D9),ISNUMBER(H9)),H9/D9,"") -> 0.6214986 | R9: ='India Sites 2020'!J9 -> 52828 | S9: =L9/R9-1 -> 0.051942152
A10: Stomach | B10: Site | C10: Digestive system | D10: 34353 | E10: 4.6 | F10: 5.2 | G10: 160 | H10: 18353 | I10: 2.6 | J10: 2.7 | K10: 319 | L10: 52706 | M10: 3.6 | N10: 3.9 | O10: 213 | P10: =L10/L$2 -> 0.03606475 | Q10: =IF(AND(ISNUMBER(D10),ISNUMBER(H10)),H10/D10,"") -> 0.53424737 | R10: ='India Sites 2020'!J10 -> 50143 | S10: =L10/R10-1 -> 0.051113814
A11: Small intestine | B11: Site | C11: Digestive system | D11: 2255 | E11: 0.3 | F11: 0.3 | G11: 2498 | H11: 1533 | I11: 0.2 | J11: 0.2 | K11: 3877 | L11: 3788 | M11: 0.3 | N11: 0.3 | O11: 3041 | P11: =L11/L$2 -> 0.0025919871 | Q11: =IF(AND(ISNUMBER(D11),ISNUMBER(H11)),H11/D11,"") -> 0.67982262 | R11: ='India Sites 2020'!J11 -> 3606 | S11: =L11/R11-1 -> 0.050471436
A12: Colon | B12: Site | C12: Digestive system | D12: 21595 | E12: 2.9 | F12: 3.2 | G12: 260 | H12: 16512 | I12: 2.3 | J12: 2.4 | K12: 348 | L12: 38107 | M12: 2.6 | N12: 2.8 | O12: 298 | P12: =L12/L$2 -> 0.026075199 | Q12: =IF(AND(ISNUMBER(D12),ISNUMBER(H12)),H12/D12,"") -> 0.76462144 | R12: ='India Sites 2020'!J12 -> 36257 | S12: =L12/R12-1 -> 0.05102463
A13: Rectum | B13: Site | C13: Digestive system | D13: 22985 | E13: 3.1 | F13: 3.4 | G13: 244 | H13: 15767 | I13: 2.2 | J13: 2.3 | K13: 372 | L13: 38752 | M13: 2.7 | N13: 2.8 | O13: 295 | P13: =L13/L$2 -> 0.026516549 | Q13: =IF(AND(ISNUMBER(D13),ISNUMBER(H13)),H13/D13,"") -> 0.68596911 | R13: ='India Sites 2020'!J13 -> 36900 | S13: =L13/R13-1 -> 0.050189702
A14: Anus, anal canal | B14: Site | C14: Digestive system | D14: 3037 | E14: 0.4 | F14: 0.4 | G14: 1865 | H14: 2131 | I14: 0.3 | J14: 0.3 | K14: 2682 | L14: 5168 | M14: 0.4 | N14: 0.4 | O14: 2200 | P14: =L14/L$2 -> 0.0035362697 | Q14: =IF(AND(ISNUMBER(D14),ISNUMBER(H14)),H14/D14,"") -> 0.70167929 | R14: ='India Sites 2020'!J14 -> 4925 | S14: =L14/R14-1 -> 0.049340102
A15: Liver and intrahepatic bile duct | B15: Site | C15: Digestive system | D15: 28020 | E15: 3.8 | F15: 4.3 | G15: 189 | H15: 11306 | I15: 1.6 | J15: 1.7 | K15: 514 | L15: 39326 | M15: 2.7 | N15: 3 | O15: 276 | P15: =L15/L$2 -> 0.026909315 | Q15: =IF(AND(ISNUMBER(D15),ISNUMBER(H15)),H15/D15,"") -> 0.4034975 | R15: ='India Sites 2020'!J15 -> 37410 | S15: =L15/R15-1 -> 0.051216252
A16: Gallbladder and other biliary | B16: Site | C16: Digestive system | D16: 12997 | E16: 1.7 | F16: 1.9 | G16: 423 | H16: 20570 | I16: 2.9 | J16: 3 | K16: 283 | L16: 33567 | M16: 2.3 | N16: 2.5 | O16: 339 | P16: =L16/L$2 -> 0.022968646 | Q16: =IF(AND(ISNUMBER(D16),ISNUMBER(H16)),H16/D16,"") -> 1.5826729 | R16: ='India Sites 2020'!J16 -> 31895 | S16: =L16/R16-1 -> 0.05242201
A17: Pancreas | B17: Site | C17: Digestive system | D17: 12511 | E17: 1.7 | F17: 1.9 | G17: 429 | H17: 8557 | I17: 1.2 | J17: 1.3 | K17: 656 | L17: 21068 | M17: 1.4 | N17: 1.6 | O17: 519 | P17: =L17/L$2 -> 0.014416047 | Q17: =IF(AND(ISNUMBER(D17),ISNUMBER(H17)),H17/D17,"") -> 0.68395812 | R17: ='India Sites 2020'!J17 -> 20018 | S17: =L17/R17-1 -> 0.052452792
A18: Respiratory system | B18: Group | D18: 108848 | E18: 14.6 | F18: 16.2 | G18: 48 | H18: 34214 | I18: 4.8 | J18: 4.8 | K18: 165 | L18: 143062 | M18: 9.8 | N18: 10.4 | O18: 74 | P18: =L18/L$2 -> 0.097891992 | Q18: =IF(AND(ISNUMBER(D18),ISNUMBER(H18)),H18/D18,"") -> 0.31432824 | R18: ='India Sites 2020'!J18 -> 136032 | S18: =L18/R18-1 -> 0.051679017
A19: Larynx | B19: Site | C19: Respiratory system | D19: 28542 | E19: 3.8 | F19: 4.3 | G19: 184 | H19: 3498 | I19: 0.5 | J19: 0.5 | K19: 1629 | L19: 32040 | M19: 2.2 | N19: 2.4 | O19: 331 | P19: =L19/L$2 -> 0.021923777 | Q19: =IF(AND(ISNUMBER(D19),ISNUMBER(H19)),H19/D19,"") -> 0.12255623 | R19: ='India Sites 2020'!J19 -> 30462 | S19: =L19/R19-1 -> 0.051802245
A20: Lung and bronchus | B20: Site | C20: Respiratory system | D20: 75474 | E20: 10.1 | F20: 11.6 | G20: 67 | H20: 27897 | I20: 3.9 | J20: 4.1 | K20: 209 | L20: 103371 | M20: 7.1 | N20: 7.8 | O20: 101 | P20: =L20/L$2 -> 0.070732921 | Q20: =IF(AND(ISNUMBER(D20),ISNUMBER(H20)),H20/D20,"") -> 0.36962398 | R20: ='India Sites 2020'!J20 -> 98278 | S20: =L20/R20-1 -> 0.051822381
A21: Other respiratory organs | B21: Site | C21: Respiratory system | D21: 4832 | E21: 0.6 | F21: 0.3 | G21: 1274 | H21: 2819 | I21: 0.4 | J21: 0.2 | K21: 2149 | L21: 7651 | M21: 0.5 | N21: 0.2 | O21: 1602 | P21: =L21/L$2 -> 0.005235294 | Q21: =IF(AND(ISNUMBER(D21),ISNUMBER(H21)),H21/D21,"") -> 0.58340232 | R21: ='India Sites 2020'!J21 -> 7292 | S21: =L21/R21-1 -> 0.049232035
A22: Bones and joints | B22: Group | D22: 8426 | E22: 1.1 | F22: 1.1 | G22: 1011 | H22: 6087 | I22: 0.9 | J22: 0.8 | K22: 1365 | L22: 14513 | M22: 1 | N22: 1 | O22: 1160 | P22: =L22/L$2 -> 0.0099307047 | Q22: =IF(AND(ISNUMBER(D22),ISNUMBER(H22)),H22/D22,"") -> 0.72240684 | R22: ='India Sites 2020'!J22 -> 13955 | S22: =L22/R22-1 -> 0.039985668
A23: Soft tissue | B23: Group | D23: 8380 | E23: 1.1 | F23: 1.2 | G23: 844 | H23: 6895 | I23: 1 | J23: 1 | K23: 1050 | L23: 15275 | M23: 1 | N23: 1.1 | O23: 936 | P23: =L23/L$2 -> 0.010452113 | Q23: =IF(AND(ISNUMBER(D23),ISNUMBER(H23)),H23/D23,"") -> 0.82279236 | R23: ='India Sites 2020'!J23 -> 14637 | S23: =L23/R23-1 -> 0.043588167
A24: Skin (excluding basal and squamous) | B24: Group | D24: 11745 | E24: 1.6 | F24: 1.7 | G24: 510 | H24: 9412 | I24: 1.3 | J24: 1.4 | K24: 641 | L24: 21157 | M24: 1.5 | N24: 1.5 | O24: 569 | P24: =L24/L$2 -> 0.014476946 | Q24: =IF(AND(ISNUMBER(D24),ISNUMBER(H24)),H24/D24,"") -> 0.80136228 | R24: ='India Sites 2020'!J24 -> 20165 | S24: =L24/R24-1 -> 0.049194148
A25: Melanoma of the skin | B25: Site | C25: Skin (excluding basal and squamous) | D25: 3145 | E25: 0.4 | F25: 0.5 | G25: 1909 | H25: 2479 | I25: 0.3 | J25: 0.4 | K25: 2288 | L25: 5624 | M25: 0.4 | N25: 0.4 | O25: 2081 | P25: =L25/L$2 -> 0.0038482935 | Q25: =IF(AND(ISNUMBER(D25),ISNUMBER(H25)),H25/D25,"") -> 0.78823529 | R25: ='India Sites 2020'!J25 -> 5367 | S25: =L25/R25-1 -> 0.047885225
A26: Other non-epithelial skin | B26: Site | C26: Skin (excluding basal and squamous) | D26: 8600 | E26: 1.2 | F26: 1.3 | G26: 696 | H26: 6933 | I26: 1 | J26: 1 | K26: 891 | L26: 15533 | M26: 1.1 | N26: 1.1 | O26: 782 | P26: =L26/L$2 -> 0.010628653 | Q26: =IF(AND(ISNUMBER(D26),ISNUMBER(H26)),H26/D26,"") -> 0.80616279 | R26: ='India Sites 2020'!J26 -> 14798 | S26: =L26/R26-1 -> 0.049668874
A27: Breast | B27: Group | D27: 5649 | E27: 0.8 | F27: 0.8 | G27: 1021 | H27: 216108 | I27: 30.4 | J27: 31.2 | K27: 29 | L27: 221757 | M27: 15.2 | N27: 16 | O27: 56 | P27: =L27/L$2 -> 0.15174005 | Q27: =IF(AND(ISNUMBER(D27),ISNUMBER(H27)),H27/D27,"") -> 38.255975 | R27: ='India Sites 2020'!J27 -> 210801 | S27: =L27/R27-1 -> 0.051973188
A28: Genital system | B28: Group | D28: 54625 | E28: 7.3 | F28: 8.4 | G28: 105 | H28: 163694 | I28: 23 | J28: 23.9 | K28: 37 | L28: 218319 | M28: 15 | N28: 16 | O28: 53 | P28: =L28/L$2 -> 0.14938755 | Q28: =IF(AND(ISNUMBER(D28),ISNUMBER(H28)),H28/D28,"") -> 2.9966865 | R28: ='India Sites 2020'!J28 -> 207624 | S28: =L28/R28-1 -> 0.051511386
A29: Uterine cervix | B29: Site | C29: Genital system | H29: 79103 | I29: 11.1 | J29: 11.6 | K29: 75 | L29: 79103 | M29: 11.1 | N29: 11.6 | O29: 75 | P29: =L29/L$2 -> 0.054127233 | Q29: =IF(AND(ISNUMBER(D29),ISNUMBER(H29)),H29/D29,"") | R29: ='India Sites 2020'!J29 -> 75209 | S29: =L29/R29-1 -> 0.051775718
A30: Uterine corpus | B30: Site | C30: Genital system | H30: 27922 | I30: 3.9 | J30: 4.2 | K30: 190 | L30: 27922 | M30: 3.9 | N30: 4.2 | O30: 190 | P30: =L30/L$2 -> 0.019105983 | Q30: =IF(AND(ISNUMBER(D30),ISNUMBER(H30)),H30/D30,"") | R30: ='India Sites 2020'!J30 -> 26514 | S30: =L30/R30-1 -> 0.053104021
A31: Ovary | B31: Site | C31: Genital system | H31: 46126 | I31: 6.5 | J31: 6.7 | K31: 133 | L31: 46126 | M31: 6.5 | N31: 6.7 | O31: 133 | P31: =L31/L$2 -> 0.031562302 | Q31: =IF(AND(ISNUMBER(D31),ISNUMBER(H31)),H31/D31,"") | R31: ='India Sites 2020'!J31 -> 43886 | S31: =L31/R31-1 -> 0.051041334
A32: Vulva | B32: Site | C32: Genital system | H32: 2258 | I32: 0.3 | J32: 0.3 | K32: 2454 | L32: 2258 | M32: 0.3 | N32: 0.3 | O32: 2454 | P32: =L32/L$2 -> 0.0015450652 | Q32: =IF(AND(ISNUMBER(D32),ISNUMBER(H32)),H32/D32,"") | R32: ='India Sites 2020'!J32 -> 2138 | S32: =L32/R32-1 -> 0.056127222
A33: Vagina and other genital, female | B33: Site | C33: Genital system | H33: 7961 | I33: 1.1 | J33: 1.2 | K33: 747 | L33: 7961 | M33: 1.1 | N33: 1.2 | O33: 747 | P33: =L33/L$2 -> 0.0054474154 | Q33: =IF(AND(ISNUMBER(D33),ISNUMBER(H33)),H33/D33,"") | R33: ='India Sites 2020'!J33 -> 7570 | S33: =L33/R33-1 -> 0.051651255
A34: Placenta | B34: Site | C34: Genital system | H34: 324 | I34: 0 | J34: 0 | K34: 31252 | L34: 324 | M34: 0 | N34: 0 | O34: 31252 | P34: =L34/L$2 -> 0.00022170112 | Q34: =IF(AND(ISNUMBER(D34),ISNUMBER(H34)),H34/D34,"") | R34: ='India Sites 2020'!J34 -> 313 | S34: =L34/R34-1 -> 0.03514377
A35: Prostate | B35: Site | C35: Genital system | D35: 43691 | E35: 5.9 | F35: 6.8 | G35: 125 | L35: 43691 | M35: 5.9 | N35: 6.8 | O35: 125 | P35: =L35/L$2 -> 0.029896122 | Q35: =IF(AND(ISNUMBER(D35),ISNUMBER(H35)),H35/D35,"") | R35: ='India Sites 2020'!J35 -> 41532 | S35: =L35/R35-1 -> 0.051984012
A36: Testis | B36: Site | C36: Genital system | D36: 4521 | E36: 0.6 | F36: 0.6 | G36: 2092 | L36: 4521 | M36: 0.6 | N36: 0.6 | O36: 2092 | P36: =L36/L$2 -> 0.0030935517 | Q36: =IF(AND(ISNUMBER(D36),ISNUMBER(H36)),H36/D36,"") | R36: ='India Sites 2020'!J36 -> 4352 | S36: =L36/R36-1 -> 0.038832721
A37: Penis and other genital, male | B37: Site | C37: Genital system | D37: 6413 | E37: 0.8 | F37: 1 | G37: 917 | L37: 6413 | M37: 0.8 | N37: 1 | O37: 917 | P37: =L37/L$2 -> 0.0043881768 | Q37: =IF(AND(ISNUMBER(D37),ISNUMBER(H37)),H37/D37,"") | R37: ='India Sites 2020'!J37 -> 6110 | S37: =L37/R37-1 -> 0.049590835
A38: Urinary system | B38: Group | D38: 34942 | E38: 4.7 | F38: 5.3 | G38: 158 | H38: 11861 | I38: 1.7 | J38: 1.8 | K38: 500 | L38: 46803 | M38: 3.2 | N38: 3.5 | O38: 240 | P38: =L38/L$2 -> 0.032025548 | Q38: =IF(AND(ISNUMBER(D38),ISNUMBER(H38)),H38/D38,"") -> 0.33944823 | R38: ='India Sites 2020'!J38 -> 44534 | S38: =L38/R38-1 -> 0.050949836
A39: Urinary bladder | B39: Site | C39: Urinary system | D39: 21523 | E39: 2.9 | F39: 3.3 | G39: 250 | H39: 5713 | I39: 0.8 | J39: 0.8 | K39: 1011 | L39: 27236 | M39: 1.9 | N39: 2 | O39: 402 | P39: =L39/L$2 -> 0.018636579 | Q39: =IF(AND(ISNUMBER(D39),ISNUMBER(H39)),H39/D39,"") -> 0.26543697 | R39: ='India Sites 2020'!J39 -> 25873 | S39: =L39/R39-1 -> 0.0526804
A40: Kidney and renal pelvis | B40: Site | C40: Urinary system | D40: 12963 | E40: 1.7 | F40: 2 | G40: 442 | H40: 5930 | I40: 0.8 | J40: 0.9 | K40: 1036 | L40: 18893 | M40: 1.3 | N40: 1.4 | O40: 619 | P40: =L40/L$2 -> 0.012927775 | Q40: =IF(AND(ISNUMBER(D40),ISNUMBER(H40)),H40/D40,"") -> 0.45745584 | R40: ='India Sites 2020'!J40 -> 18020 | S40: =L40/R40-1 -> 0.048446171
...

Sheet India Sites 2020
A1: Site (ICD-10 group) | B1: Level | C1: Parent group | D1: Male - projected cases 2020 | E1: Male - crude rate /100,000 | F1: Male - cum. risk 0-74 (1 in N) | G1: Female - projected cases 2020 | H1: Female - crude rate /100,000 | I1: Female - cum. risk 0-74 (1 in N) | J1: Both sexes - projected cases 2020 | K1: Both sexes - crude rate /100,000 | L1: Both sexes - cum. risk 0-74 (1 in N) | M1: Share of all-site cases (both sexes) | N1: Female : male case ratio
A2: All sites | B2: Total | D2: 679421 | E2: 94.1 | F2: 9 | G2: 712758 | H2: 103.6 | I2: 9 | J2: 1392179 | K2: 98.7 | L2: 9 | M2: =J2/J$2 -> 1 | N2: =IF(AND(ISNUMBER(D2),ISNUMBER(G2)),G2/D2,"") -> 1.0490668
A3: Oral cavity and pharynx | B3: Group | D3: 139018 | E3: 19.2 | F3: 41 | G3: 49951 | H3: 7.3 | I3: 112 | J3: 188969 | K3: 13.4 | L3: 60 | M3: =J3/J$2 -> 0.13573614 | N3: =IF(AND(ISNUMBER(D3),ISNUMBER(G3)),G3/D3,"") -> 0.35931318
A4: Tongue | B4: Site | C4: Oral cavity and pharynx | D4: 39902 | E4: 5.5 | F4: 147 | G4: 13870 | H4: 2 | I4: 401 | J4: 53772 | K4: 3.8 | L4: 215 | M4: =J4/J$2 -> 0.038624344 | N4: =IF(AND(ISNUMBER(D4),ISNUMBER(G4)),G4/D4,"") -> 0.34760162
A5: Mouth | B5: Site | C5: Oral cavity and pharynx | D5: 57380 | E5: 7.9 | F5: 103 | G5: 22483 | H5: 3.3 | I5: 241 | J5: 79863 | K5: 5.7 | L5: 144 | M5: =J5/J$2 -> 0.057365468 | N5: =IF(AND(ISNUMBER(D5),ISNUMBER(G5)),G5/D5,"") -> 0.39182642
A6: Pharynx | B6: Site | C6: Oral cavity and pharynx | D6: 3029 | E6: 0.4 | F6: 1793 | G6: 1102 | H6: 0.2 | I6: 5475 | J6: 4131 | K6: 0.3 | L6: 2701 | M6: =J6/J$2 -> 0.0029672908 | N6: =IF(AND(ISNUMBER(D6),ISNUMBER(G6)),G6/D6,"") -> 0.36381644
A7: Other oral cavity | B7: Site | C7: Oral cavity and pharynx | D7: 38707 | E7: 5.4 | F7: 137 | G7: 12496 | H7: 1.8 | I7: 476 | J7: 51203 | K7: 3.6 | L7: 213 | M7: =J7/J$2 -> 0.036779035 | N7: =IF(AND(ISNUMBER(D7),ISNUMBER(G7)),G7/D7,"") -> 0.32283566
A8: Digestive system | B8: Group | D8: 163845 | E8: 22.7 | F8: 32 | G8: 110137 | H8: 16 | I8: 50 | J8: 273982 | K8: 19.4 | L8: 39 | M8: =J8/J$2 -> 0.19680084 | N8: =IF(AND(ISNUMBER(D8),ISNUMBER(G8)),G8/D8,"") -> 0.67220239
A9: Oesophagus | B9: Site | C9: Digestive system | D9: 32622 | E9: 4.5 | F9: 159 | G9: 20206 | H9: 2.9 | I9: 264 | J9: 52828 | K9: 3.7 | L9: 198 | M9: =J9/J$2 -> 0.03794627 | N9: =IF(AND(ISNUMBER(D9),ISNUMBER(G9)),G9/D9,"") -> 0.61939795
A10: Stomach | B10: Site | C10: Digestive system | D10: 32713 | E10: 4.5 | F10: 160 | G10: 17430 | H10: 2.5 | I10: 319 | J10: 50143 | K10: 3.6 | L10: 213 | M10: =J10/J$2 -> 0.036017639 | N10: =IF(AND(ISNUMBER(D10),ISNUMBER(G10)),G10/D10,"") -> 0.5328157
A11: Small intestine | B11: Site | C11: Digestive system | D11: 2155 | E11: 0.3 | F11: 2492 | G11: 1451 | H11: 0.2 | I11: 3901 | J11: 3606 | K11: 0.3 | L11: 3044 | M11: =J11/J$2 -> 0.0025901842 | N11: =IF(AND(ISNUMBER(D11),ISNUMBER(G11)),G11/D11,"") -> 0.67331787
A12: Colon | B12: Site | C12: Digestive system | D12: 20572 | E12: 2.8 | F12: 260 | G12: 15685 | H12: 2.3 | I12: 348 | J12: 36257 | K12: 2.6 | L12: 298 | M12: =J12/J$2 -> 0.026043346 | N12: =IF(AND(ISNUMBER(D12),ISNUMBER(G12)),G12/D12,"") -> 0.7624441
A13: Rectum | B13: Site | C13: Digestive system | D13: 21915 | E13: 3 | F13: 244 | G13: 14985 | H13: 2.2 | I13: 372 | J13: 36900 | K13: 2.6 | L13: 295 | M13: =J13/J$2 -> 0.026505212 | N13: =IF(AND(ISNUMBER(D13),ISNUMBER(G13)),G13/D13,"") -> 0.68377823
A14: Anus, anal canal | B14: Site | C14: Digestive system | D14: 2897 | E14: 0.4 | F14: 1865 | G14: 2028 | H14: 0.3 | I14: 2682 | J14: 4925 | K14: 0.3 | L14: 2200 | M14: =J14/J$2 -> 0.0035376198 | N14: =IF(AND(ISNUMBER(D14),ISNUMBER(G14)),G14/D14,"") -> 0.70003452
A15: Liver and intrahepatic bile duct | B15: Site | C15: Digestive system | D15: 26678 | E15: 3.7 | F15: 189 | G15: 10732 | H15: 1.6 | I15: 514 | J15: 37410 | K15: 2.7 | L15: 277 | M15: =J15/J$2 -> 0.026871545 | N15: =IF(AND(ISNUMBER(D15),ISNUMBER(G15)),G15/D15,"") -> 0.40227903
A16: Gallbladder and other biliary | B16: Site | C16: Digestive system | D16: 12385 | E16: 1.7 | F16: 422 | G16: 19510 | H16: 2.8 | I16: 284 | J16: 31895 | K16: 2.3 | L16: 340 | M16: =J16/J$2 -> 0.022910129 | N16: =IF(AND(ISNUMBER(D16),ISNUMBER(G16)),G16/D16,"") -> 1.5752927
A17: Pancreas | B17: Site | C17: Digestive system | D17: 11908 | E17: 1.6 | F17: 429 | G17: 8110 | H17: 1.2 | I17: 657 | J17: 20018 | K17: 1.4 | L17: 519 | M17: =J17/J$2 -> 0.014378898 | N17: =IF(AND(ISNUMBER(D17),ISNUMBER(G17)),G17/D17,"") -> 0.68105475
A18: Respiratory system | B18: Group | D18: 103552 | E18: 14.3 | F18: 48 | G18: 32480 | H18: 4.7 | I18: 165 | J18: 136032 | K18: 9.6 | L18: 74 | M18: =J18/J$2 -> 0.097711573 | N18: =IF(AND(ISNUMBER(D18),ISNUMBER(G18)),G18/D18,"") -> 0.31365884
A19: Larynx | B19: Site | C19: Respiratory system | D19: 27146 | E19: 3.8 | F19: 184 | G19: 3316 | H19: 0.5 | I19: 1633 | J19: 30462 | K19: 2.2 | L19: 331 | M19: =J19/J$2 -> 0.021880807 | N19: =IF(AND(ISNUMBER(D19),ISNUMBER(G19)),G19/D19,"") -> 0.12215428
A20: Lung and bronchus | B20: Site | C20: Respiratory system | D20: 71788 | E20: 9.9 | F20: 68 | G20: 26490 | H20: 3.9 | I20: 201 | J20: 98278 | K20: 7 | L20: 101 | M20: =J20/J$2 -> 0.070592934 | N20: =IF(AND(ISNUMBER(D20),ISNUMBER(G20)),G20/D20,"") -> 0.36900318
A21: Other respiratory organs | B21: Site | C21: Respiratory system | D21: 4618 | E21: 0.6 | F21: 1273 | G21: 2674 | H21: 0.4 | I21: 2156 | J21: 7292 | K21: 0.5 | L21: 1600 | M21: =J21/J$2 -> 0.0052378322 | N21: =IF(AND(ISNUMBER(D21),ISNUMBER(G21)),G21/D21,"") -> 0.57903854
A22: Bones and joints | B22: Group | D22: 8115 | E22: 1.1 | F22: 1013 | G22: 5840 | H22: 0.8 | I22: 1370 | J22: 13955 | K22: 1 | L22: 1162 | M22: =J22/J$2 -> 0.010023855 | N22: =IF(AND(ISNUMBER(D22),ISNUMBER(G22)),G22/D22,"") -> 0.71965496
A23: Soft tissue | B23: Group | D23: 8047 | E23: 1.1 | F23: 842 | G23: 6590 | H23: 1 | I23: 1052 | J23: 14637 | K23: 1 | L23: 936 | M23: =J23/J$2 -> 0.010513734 | N23: =IF(AND(ISNUMBER(D23),ISNUMBER(G23)),G23/D23,"") -> 0.81893873
A24: Skin (excluding basal and squamous) | B24: Group | D24: 11203 | E24: 1.6 | F24: 510 | G24: 8962 | H24: 1.3 | I24: 640 | J24: 20165 | K24: 1.4 | L24: 568 | M24: =J24/J$2 -> 0.014484488 | N24: =IF(AND(ISNUMBER(D24),ISNUMBER(G24)),G24/D24,"") -> 0.7999643
A25: Melanoma of the skin | B25: Site | C25: Skin (excluding basal and squamous) | D25: 3003 | E25: 0.4 | F25: 1904 | G25: 2364 | H25: 0.3 | I25: 2281 | J25: 5367 | K25: 0.4 | L25: 2075 | M25: =J25/J$2 -> 0.0038551077 | N25: =IF(AND(ISNUMBER(D25),ISNUMBER(G25)),G25/D25,"") -> 0.78721279
A26: Other non-epithelial skin | B26: Site | C26: Skin (excluding basal and squamous) | D26: 8200 | E26: 1.1 | F26: 695 | G26: 6598 | H26: 1 | I26: 890 | J26: 14798 | K26: 1 | L26: 781 | M26: =J26/J$2 -> 0.01062938 | N26: =IF(AND(ISNUMBER(D26),ISNUMBER(G26)),G26/D26,"") -> 0.80463415
A27: Breast | B27: Group | D27: 5377 | E27: 0.7 | F27: 1022 | G27: 205424 | H27: 29.9 | I27: 29 | J27: 210801 | K27: 15 | L27: 56 | M27: =J27/J$2 -> 0.15141803 | N27: =IF(AND(ISNUMBER(D27),ISNUMBER(G27)),G27/D27,"") -> 38.204203
A28: Genital system | B28: Group | D28: 51994 | E28: 7.2 | F28: 105 | G28: 155630 | H28: 22.6 | I28: 36 | J28: 207624 | K28: 14.7 | L28: 54 | M28: =J28/J$2 -> 0.14913599 | N28: =IF(AND(ISNUMBER(D28),ISNUMBER(G28)),G28/D28,"") -> 2.99323
A29: Uterine cervix | B29: Site | C29: Genital system | G29: 75209 | H29: 10.9 | I29: 75 | J29: 75209 | K29: 10.9 | L29: 75 | M29: =J29/J$2 -> 0.054022507 | N29: =IF(AND(ISNUMBER(D29),ISNUMBER(G29)),G29/D29,"")
A30: Uterine corpus | B30: Site | C30: Genital system | G30: 26514 | H30: 3.9 | I30: 190 | J30: 26514 | K30: 3.9 | L30: 190 | M30: =J30/J$2 -> 0.019044965 | N30: =IF(AND(ISNUMBER(D30),ISNUMBER(G30)),G30/D30,"")
A31: Ovary | B31: Site | C31: Genital system | G31: 43886 | H31: 6.4 | I31: 133 | J31: 43886 | K31: 6.4 | L31: 133 | M31: =J31/J$2 -> 0.031523245 | N31: =IF(AND(ISNUMBER(D31),ISNUMBER(G31)),G31/D31,"")
A32: Vulva | B32: Site | C32: Genital system | G32: 2138 | H32: 0.3 | I32: 2459 | J32: 2138 | K32: 0.3 | L32: 2459 | M32: =J32/J$2 -> 0.0015357221 | N32: =IF(AND(ISNUMBER(D32),ISNUMBER(G32)),G32/D32,"")
A33: Vagina and other genital, female | B33: Site | C33: Genital system | G33: 7570 | H33: 1.1 | I33: 745 | J33: 7570 | K33: 1.1 | L33: 745 | M33: =J33/J$2 -> 0.0054375192 | N33: =IF(AND(ISNUMBER(D33),ISNUMBER(G33)),G33/D33,"")
A34: Placenta | B34: Site | C34: Genital system | G34: 313 | H34: 0 | I34: 30912 | J34: 313 | K34: 0 | L34: 30912 | M34: =J34/J$2 -> 0.00022482741 | N34: =IF(AND(ISNUMBER(D34),ISNUMBER(G34)),G34/D34,"")
A35: Prostate | B35: Site | C35: Genital system | D35: 41532 | E35: 5.7 | F35: 125 | J35: 41532 | K35: 5.7 | L35: 125 | M35: =J35/J$2 -> 0.029832371 | N35: =IF(AND(ISNUMBER(D35),ISNUMBER(G35)),G35/D35,"")
A36: Testis | B36: Site | C36: Genital system | D36: 4352 | E36: 0.6 | F36: 2095 | J36: 4352 | K36: 0.6 | L36: 2095 | M36: =J36/J$2 -> 0.0031260348 | N36: =IF(AND(ISNUMBER(D36),ISNUMBER(G36)),G36/D36,"")
A37: Penis and other genital, male | B37: Site | C37: Genital system | D37: 6110 | E37: 0.8 | F37: 916 | J37: 6110 | K37: 0.8 | L37: 916 | M37: =J37/J$2 -> 0.0043888035 | N37: =IF(AND(ISNUMBER(D37),ISNUMBER(G37)),G37/D37,"")
A38: Urinary system | B38: Group | D38: 33269 | E38: 4.6 | F38: 158 | G38: 11265 | H38: 1.6 | I38: 502 | J38: 44534 | K38: 3.2 | L38: 240 | M38: =J38/J$2 -> 0.031988703 | N38: =IF(AND(ISNUMBER(D38),ISNUMBER(G38)),G38/D38,"") -> 0.3386035
A39: Urinary bladder | B39: Site | C39: Urinary system | D39: 20470 | E39: 2.8 | F39: 250 | G39: 5403 | H39: 0.8 | I39: 1014 | J39: 25873 | K39: 1.8 | L39: 402 | M39: =J39/J$2 -> 0.018584535 | N39: =IF(AND(ISNUMBER(D39),ISNUMBER(G39)),G39/D39,"") -> 0.26394724
A40: Kidney and renal pelvis | B40: Site | C40: Urinary system | D40: 12363 | E40: 1.7 | F40: 442 | G40: 5657 | H40: 0.8 | I40: 1038 | J40: 18020 | K40: 1.3 | L40: 620 | M40: =J40/J$2 -> 0.012943738 | N40: =IF(AND(ISNUMBER(D40),ISNUMBER(G40)),G40/D40,"") -> 0.45757502
...

Sheet India Age-Sex Sites
A1: Age group | B1: Sex | C1: Rank | D1: Cancer site | E1: ICD-10 codes | F1: Estimated cases 2022 (n) | G1: Share of age-sex total (% as printed) | H1: Share recomputed (%) | I1: Row type | J1: Check: listed rows - All sites
A2: 0-14 yr | B2: Male | C2: 1 | D2: Lymphoid leukaemia | E2: C91 | F2: 6233 | G2: 29.3 | H2: =F2/F$8*100 -> 29.251924 | I2: Top-5 site
A3: 0-14 yr | B3: Male | C3: 2 | D3: Brain and NS | E3: C70-C72 | F3: 2643 | G3: 12.4 | H3: =F3/F$8*100 -> 12.403792 | I3: Top-5 site
A4: 0-14 yr | B4: Male | C4: 3 | D4: NHL | E4: C82-86, C96 | F4: 1679 | G4: 7.9 | H4: =F4/F$8*100 -> 7.8796696 | I4: Top-5 site
A5: 0-14 yr | B5: Male | C5: 4 | D5: Hodgkin's disease | E5: C81 | F5: 1513 | G5: 7.1 | H5: =F5/F$8*100 -> 7.1006195 | I5: Top-5 site
A6: 0-14 yr | B6: Male | C6: 5 | D6: Myeloid leukaemia | E6: C92-C94 | F6: 1498 | G6: 7 | H6: =F6/F$8*100 -> 7.0302234 | I6: Top-5 site
A7: 0-14 yr | B7: Male | D7: Other sites | F7: 7742 | G7: 36.3 | H7: =F7/F$8*100 -> 36.333771 | I7: Other
A8: 0-14 yr | B8: Male | D8: All sites | F8: 21308 | G8: 100 | H8: =F8/F$8*100 -> 100 | I8: Total | J8: =SUM(F2:F7)-F8 -> 0
A9: 0-14 yr | B9: Female | C9: 1 | D9: Lymphoid leukaemia | E9: C91 | F9: 3328 | G9: 24.3 | H9: =F9/F$15*100 -> 24.276023 | I9: Top-5 site
A10: 0-14 yr | B10: Female | C10: 2 | D10: Brain and NS | E10: C70-C72 | F10: 1956 | G10: 14.3 | H10: =F10/F$15*100 -> 14.267999 | I10: Top-5 site
A11: 0-14 yr | B11: Female | C11: 3 | D11: Bone | E11: C40-C41 | F11: 1140 | G11: 8.3 | H11: =F11/F$15*100 -> 8.315705 | I11: Top-5 site
A12: 0-14 yr | B12: Female | C12: 4 | D12: Myeloid leukaemia | E12: C92-C94 | F12: 1099 | G12: 8 | H12: =F12/F$15*100 -> 8.0166314 | I12: Top-5 site
A13: 0-14 yr | B13: Female | C13: 5 | D13: NHL | E13: C82-86, C96 | F13: 783 | G13: 5.7 | H13: =F13/F$15*100 -> 5.7115763 | I13: Top-5 site
A14: 0-14 yr | B14: Female | D14: Other sites | F14: 5403 | G14: 39.4 | H14: =F14/F$15*100 -> 39.412065 | I14: Other
A15: 0-14 yr | B15: Female | D15: All sites | F15: 13709 | G15: 100 | H15: =F15/F$15*100 -> 100 | I15: Total | J15: =SUM(F9:F14)-F15 -> 0
A16: 15-39 yr | B16: Male | C16: 1 | D16: Mouth | E16: C03-C06 | F16: 9013 | G16: 12 | H16: =F16/F$22*100 -> 12.037878 | I16: Top-5 site
A17: 15-39 yr | B17: Male | C17: 2 | D17: Tongue | E17: C01-C02 | F17: 6597 | G17: 8.8 | H17: =F17/F$22*100 -> 8.8110375 | I17: Top-5 site
A18: 15-39 yr | B18: Male | C18: 3 | D18: Brain and NS | E18: C70-C72 | F18: 5230 | G18: 7 | H18: =F18/F$22*100 -> 6.9852548 | I18: Top-5 site
A19: 15-39 yr | B19: Male | C19: 4 | D19: Myeloid leukaemia | E19: C92-C94 | F19: 4881 | G19: 6.5 | H19: =F19/F$22*100 -> 6.519126 | I19: Top-5 site
A20: 15-39 yr | B20: Male | C20: 5 | D20: NHL | E20: C82-86, C96 | F20: 4444 | G20: 5.9 | H20: =F20/F$22*100 -> 5.9354632 | I20: Top-5 site
A21: 15-39 yr | B21: Male | D21: Other sites | F21: 44707 | G21: 59.7 | H21: =F21/F$22*100 -> 59.711241 | I21: Other
A22: 15-39 yr | B22: Male | D22: All sites | F22: 74872 | G22: 100 | H22: =F22/F$22*100 -> 100 | I22: Total | J22: =SUM(F16:F21)-F22 -> 0
A23: 15-39 yr | B23: Female | C23: 1 | D23: Breast | E23: C50 | F23: 25710 | G23: 27.3 | H23: =F23/F$29*100 -> 27.302848 | I23: Top-5 site
A24: 15-39 yr | B24: Female | C24: 2 | D24: Thyroid | E24: C73 | F24: 11453 | G24: 12.2 | H24: =F24/F$29*100 -> 12.162564 | I24: Top-5 site
A25: 15-39 yr | B25: Female | C25: 3 | D25: Ovary | E25: C56 | F25: 6877 | G25: 7.3 | H25: =F25/F$29*100 -> 7.3030606 | I25: Top-5 site
A26: 15-39 yr | B26: Female | C26: 4 | D26: Cervix | E26: C53 | F26: 6714 | G26: 7.1 | H26: =F26/F$29*100 -> 7.129962 | I26: Top-5 site
A27: 15-39 yr | B27: Female | C27: 5 | D27: Myeloid leukaemia | E27: C92-C94 | F27: 3503 | G27: 3.7 | H27: =F27/F$29*100 -> 3.7200263 | I27: Top-5 site
A28: 15-39 yr | B28: Female | D28: Other sites | F28: 39909 | G28: 42.4 | H28: =F28/F$29*100 -> 42.381539 | I28: Other
A29: 15-39 yr | B29: Female | D29: All sites | F29: 94166 | G29: 100 | H29: =F29/F$29*100 -> 100 | I29: Total | J29: =SUM(F23:F28)-F29 -> 0
A30: 40-64 yr | B30: Male | C30: 1 | D30: Lung | E30: C33-34 | F30: 37376 | G30: 11 | H30: =F30/F$36*100 -> 10.953316 | I30: Top-5 site
A31: 40-64 yr | B31: Male | C31: 2 | D31: Mouth | E31: C03-C06 | F31: 37067 | G31: 10.9 | H31: =F31/F$36*100 -> 10.862761 | I31: Top-5 site
A32: 40-64 yr | B32: Male | C32: 3 | D32: Tongue | E32: C01-C02 | F32: 24951 | G32: 7.3 | H32: =F32/F$36*100 -> 7.3120769 | I32: Top-5 site
A33: 40-64 yr | B33: Male | C33: 4 | D33: Oesophagus | E33: C15 | F33: 18390 | G33: 5.4 | H33: =F33/F$36*100 -> 5.3893268 | I33: Top-5 site
A34: 40-64 yr | B34: Male | C34: 5 | D34: Stomach | E34: C16 | F34: 17741 | G34: 5.2 | H34: =F34/F$36*100 -> 5.1991325 | I34: Top-5 site
A35: 40-64 yr | B35: Male | D35: Other sites | F35: 205705 | G35: 60.3 | H35: =F35/F$36*100 -> 60.283387 | I35: Other
A36: 40-64 yr | B36: Male | D36: All sites | F36: 341230 | G36: 100 | H36: =F36/F$36*100 -> 100 | I36: Total | J36: =SUM(F30:F35)-F36 -> 0
A37: 40-64 yr | B37: Female | C37: 1 | D37: Breast | E37: C50 | F37: 140384 | G37: 33 | H37: =F37/F$43*100 -> 32.960335 | I37: Top-5 site
A38: 40-64 yr | B38: Female | C38: 2 | D38: Cervix | E38: C53 | F38: 52560 | G38: 12.3 | H38: =F38/F$43*100 -> 12.340404 | I38: Top-5 site
A39: 40-64 yr | B39: Female | C39: 3 | D39: Ovary | E39: C56 | F39: 27562 | G39: 6.5 | H39: =F39/F$43*100 -> 6.4711987 | I39: Top-5 site
A40: 40-64 yr | B40: Female | C40: 4 | D40: Corpus uteri | E40: C54 | F40: 18108 | G40: 4.3 | H40: =F40/F$43*100 -> 4.2515226 | I40: Top-5 site
...

Sheet India Top10 Sites 2022
A1: Sex | B1: Rank | C1: Site (as in Fig. 1) | D1: Share of all cancers (%) - Fig. 1 | E1: Matching site in Table I | F1: Estimated cases 2022 (Table I) | G1: Share recomputed from Table I (%) | H1: Difference (pct-points)
A2: Male | B2: 1 | C2: Lung | D2: 10.6 | E2: Lung and bronchus | F2: =INDEX('India Sites 2022'!$D$2:$D$56,MATCH(E2,'India Sites 2022'!$A$2:$A$56,0)) -> 75474 | G2: =F2/'India Sites 2022'!$D$2*100 -> 10.597661 | H2: =G2-D2 -> -0.0023387477
A3: Male | B3: 2 | C3: Mouth | D3: 8.4 | E3: Mouth | F3: =INDEX('India Sites 2022'!$D$2:$D$56,MATCH(E3,'India Sites 2022'!$A$2:$A$56,0)) -> 60164 | G3: =F3/'India Sites 2022'!$D$2*100 -> 8.4479118 | H3: =G3-D3 -> 0.047911752
A4: Male | B4: 3 | C4: Prostate | D4: 6.1 | E4: Prostate | F4: =INDEX('India Sites 2022'!$D$2:$D$56,MATCH(E4,'India Sites 2022'!$A$2:$A$56,0)) -> 43691 | G4: =F4/'India Sites 2022'!$D$2*100 -> 6.1348599 | H4: =G4-D4 -> 0.034859922
A5: Male | B5: 4 | C5: Tongue | D5: 5.9 | E5: Tongue | F5: =INDEX('India Sites 2022'!$D$2:$D$56,MATCH(E5,'India Sites 2022'!$A$2:$A$56,0)) -> 41845 | G5: =F5/'India Sites 2022'!$D$2*100 -> 5.8756543 | H5: =G5-D5 -> -0.024345667
